<?xml version="1.0"?>

<robot name="Puzzlebot">

    <link name="odom"/> 
  
    <joint name="chassis_joint" type="fixed">
        <parent link="odom"/>
        <child link="chassis"/>
        <origin xyz="0.0 0.0 0.1"/>
    </joint>

        <link name="chassis">
            <inertial>
                <origin xyz="0 0 0" rpy="0 0 0"/>
                <mass value="0.01" />
                <inertia ixx="7.58333333333e-06" ixy="0.0" ixz="0.0" iyy="7.58333333333e-06" iyz="0.0" izz="1.25e-05"/>
            </inertial>
            <collision>
                <origin rpy="0 0 0" xyz="0 0 0"/>
                <geometry>
                    <mesh filename="package://puzzlebot_sim/models/MCR2_1000_13_Chassis.stl"/>
                </geometry>
            </collision>
            <visual>
                <origin rpy="1.57079632679 0 1.57079632679" xyz="0 0 0"/>
                <geometry>
                    <mesh filename="package://puzzlebot_sim/models/MCR2_1000_13_Chassis.stl"/>
                </geometry>
            </visual>
        </link>

            <joint name="wr_joint" type="continuous">
                <parent link="chassis"/>
                <child link="right_wheel"/>
                <origin xyz="0.055 -0.095 -0.0025"/>
                <axis xyz="0 1 0"/>
            </joint>

            <link name="right_wheel">
                <inertial>
                    <origin xyz="0 0 0" rpy="0 0 0"/>
                    <mass value="0.01" />
                    <inertia ixx="7.58333333333e-06" ixy="0.0" ixz="0.0" iyy="7.58333333333e-06" iyz="0.0" izz="1.25e-05"/>
                </inertial>
                <collision>
                    <origin rpy="0 0 0" xyz="0 0 0"/>
                    <geometry>
                        <mesh filename="package://puzzlebot_sim/models/MCR2_1000_1_1_Wheel_Coupler_2.stl"/>
                    </geometry>
                </collision>
                <visual>
                    <origin xyz="0 0 0" rpy="-1.57079632679 0 0"/>
                    <geometry>
                        <mesh filename="package://puzzlebot_sim/models/MCR2_1000_1_1_Wheel_Coupler_2.stl"/>
                    </geometry>
                </visual>
            </link>
            
            <joint name="wl_joint" type="continuous">
                <parent link="chassis"/>
                <child link="left_wheel"/>
                <origin xyz="0.055 0.095 -0.0025"/>
                <axis xyz="0 1 0"/>
            </joint>

            <link name="left_wheel">
                <inertial>
                    <origin xyz="0 0 0" rpy="0 0 0"/>
                    <mass value="0.01" />
                    <inertia ixx="7.58333333333e-06" ixy="0.0" ixz="0.0" iyy="7.58333333333e-06" iyz="0.0" izz="1.25e-05"/>
                </inertial>
                <collision>
                    <origin rpy="0 0 0" xyz="0 0 0"/>
                    <geometry>
                        <mesh filename="package://puzzlebot_sim/models/MCR2_1000_1_1_Wheel_Coupler_2.stl"/>
                    </geometry>
                </collision>
                <visual>
                    <origin xyz="0 0 0" rpy="1.57079632679 0 0"/>
                    <geometry>
                        <mesh filename="package://puzzlebot_sim/models/MCR2_1000_1_1_Wheel_Coupler_2.stl"/>
                    </geometry>
                </visual>
            </link>
</robot>